Traceback (most recent call last):
  File "/opt/anaconda3/envs/jupyterbook/lib/python3.10/site-packages/jupyter_core/utils/__init__.py", line 154, in wrapped
    asyncio.get_running_loop()
RuntimeError: no running event loop

During handling of the above exception, another exception occurred:

Traceback (most recent call last):
  File "/opt/anaconda3/envs/jupyterbook/lib/python3.10/site-packages/jupyter_cache/executors/utils.py", line 58, in single_nb_execution
    executenb(
  File "/opt/anaconda3/envs/jupyterbook/lib/python3.10/site-packages/nbclient/client.py", line 1319, in execute
    return NotebookClient(nb=nb, resources=resources, km=km, **kwargs).execute()
  File "/opt/anaconda3/envs/jupyterbook/lib/python3.10/site-packages/jupyter_core/utils/__init__.py", line 158, in wrapped
    return loop.run_until_complete(inner)
  File "/opt/anaconda3/envs/jupyterbook/lib/python3.10/asyncio/base_events.py", line 649, in run_until_complete
    return future.result()
  File "/opt/anaconda3/envs/jupyterbook/lib/python3.10/site-packages/nbclient/client.py", line 709, in async_execute
    await self.async_execute_cell(
  File "/opt/anaconda3/envs/jupyterbook/lib/python3.10/site-packages/nbclient/client.py", line 1062, in async_execute_cell
    await self._check_raise_for_error(cell, cell_index, exec_reply)
  File "/opt/anaconda3/envs/jupyterbook/lib/python3.10/site-packages/nbclient/client.py", line 918, in _check_raise_for_error
    raise CellExecutionError.from_cell_and_msg(cell, exec_reply_content)
nbclient.exceptions.CellExecutionError: An error occurred while executing the following cell:
------------------
top5_geluk = merged.nlargest(5, 'Happiness score')
top5_depressie = merged.nlargest(5, depressie_col)
top5_angst = merged.nlargest(5, angst_col)

alle_landen = pd.concat([
    top5_geluk[['Country']],
    top5_depressie[['Country']],
    top5_angst[['Country']]
]).drop_duplicates()

relevante_data = merged[merged['Country'].isin(alle_landen['Country'])]

df_geluk = pd.DataFrame({
    'Country': relevante_data['Country'],
    'Waarde': relevante_data['Happiness score'],
    'Categorie': 'Geluksniveau'  # Alleen dit is aangepast
})

df_depressie = pd.DataFrame({
    'Country': relevante_data['Country'],
    'Waarde': relevante_data[depressie_col],
    'Categorie': 'Depressie'
})

df_angst = pd.DataFrame({
    'Country': relevante_data['Country'],
    'Waarde': relevante_data[angst_col],
    'Categorie': 'Angst'
})

df_combine = pd.concat([df_geluk, df_depressie, df_angst])

fig = px.bar(
    df_combine,
    x='Country',
    y='Waarde',
    color='Categorie',
    barmode='group',
    title='Top 5 landen in 2015: Geluksniveau, Depressie en Angst',  # ook hier aangepast
    labels={'Waarde': 'Score', 'Country': 'Land'}
)

fig.update_layout(
    title_font_size=18,
    xaxis_title='Land',
    yaxis_title='Waarde',
    legend_title='Categorie',
    bargap=0.2
)

HTML(pio.to_html(fig, include_plotlyjs='cdn'))

------------------


[0;31m---------------------------------------------------------------------------[0m
[0;31mNameError[0m                                 Traceback (most recent call last)
Cell [0;32mIn[13], line 1[0m
[0;32m----> 1[0m top5_geluk [38;5;241m=[39m [43mmerged[49m[38;5;241m.[39mnlargest([38;5;241m5[39m, [38;5;124m'[39m[38;5;124mHappiness score[39m[38;5;124m'[39m)
[1;32m      2[0m top5_depressie [38;5;241m=[39m merged[38;5;241m.[39mnlargest([38;5;241m5[39m, depressie_col)
[1;32m      3[0m top5_angst [38;5;241m=[39m merged[38;5;241m.[39mnlargest([38;5;241m5[39m, angst_col)

[0;31mNameError[0m: name 'merged' is not defined

